Workbook

Sheet Resumen
A1: Una persona gana un mensual de: | E1: 2546
A2: Tiene gastos personales anuales de: | E2: 6000 | F2: Valor de gastos personales sustentados, de preferencia mayores a CBF*7.
A3: Tiene ingresos exentos anuales por: | E3: =+E1+E1+450 -> 5542 | F3: Decimo tercero, cuarto, fondo de reserva
A5: Impuesto a la renta: | D5: Anual
A6: Si es empleado | D6: =+D35 -> 1854.6212
A7: Si es RIMPE | D7: =+E35 -> 165.5199
A8: Si no es empleado ni RIMPE | D8: =+F35 -> 2287.6958
A9: Ingresos totales | D9: =+Tabla!D34 -> 36094
B22: a | C22: El trabajador que, en el mismo período fiscal haya reiniciado su actividad con otro empleador, estará en la obligación de entregar el formulario 107 entregado por su anterior empleador a su nuevo empleador, para que aquel, efectúe el cálculo de las retenciones a realizarse en lo que resta del año.
A23: www.jezl-auditores.com | B23: b | C23: El valor de ingresos gravables debe incluir la información registrada en el campo 349 del Formulario 107 entregado por el anterior empleador, y/o con la proyección de ingresos de otros empleadores actuales, en caso de que el empleador que registra y entrega el presente formulario haya efectuado la retención por los ingresos percibidos con éstos últimos.
B24: c | C24: La deducción total por gastos personales no deberá superar el 50% del total de ingresos gravados, y en ningún caso será mayor al equivalente a 1.3 veces la fracción básica exenta de Impuesto a la Renta de personas naturales.
B25: d | C25: El trabajador deberá presentar el Anexo de Gastos Personales que cumpla las condiciones establecidas por el Servicio de Rentas Internas.
B26: e | C26: Resolución No. NAC-DGER2008-0566 RO No. 342 el 21 de mayo del 2008, el beneficio de la exoneración por tercera edad se configura a partir del ejercicio en el cual el beneficiario cumpla los 65 años de edad. El monto de la exoneración será el equivalente al doble de la fracción básica exenta de Impuesto a la Renta.
A29: CALCULO DE IMPUESTO A LA RENTA Y RETENCION DEL EMPLEADO | F29: Canasta Familiar Básica (CFB) Refer. | I29: 719.65 | J29: Se ha utilizado la CFB de Dic/21, cuando se requiere cámbiela con CBF de Dic/2022
A30: AÑO AL QUE CORRESPONDE: | D30: Empleado | E30: RIMPE | F30: Excluyente | G30: Manual del experto tributario | J30: http://bit.ly/2FHeNwQ
A32: Valor de ingresos gravables | D32: =+E1*12 -> 30552 | E32: =+D32 -> 30552 | F32: =+E32 -> 30552
A33: Aporte personal | D33: =+D32*0.0945 -> 2887.164 | E33: 0 | F33: 0
A34: Base imponible | D34: =+D32-D33 -> 27664.836 | E34: =+E32-E33 -> 30552 | F34: =+F32-F33 -> 30552
A35: Impuesto a la renta causado | D35: =+Tabla!G31 -> 1854.6212 | E35: =+Tabla!G46 -> 165.5199 | F35: =+Tabla!I31 -> 2287.6958
A36: Rebaja de impuesto a la renta | D36: =IF(Tabla!D34>Tabla!D35,Tabla!D53,Tabla!D52) -> 503.755
A37: Retenciones efectuadas | E37: Para casos de cambios en el sueldo
A38: Valor a retener | D38: =IF((D35-D36-D37)<0,0,+D35-D36-D37) -> 1350.8662
A39: Meses para retener | D39: 12 | E39: Para casos de cambios en el sueldo
A40: Retención mensual | D40: =+D38/D39 -> 112.57218
A44: Gastos personales | D44: =+E4 -> 0 | E44: 0 | F44: =+D44 -> 0
A45: Rebaja (ingresos menores a 24,090) | D45: =+Tabla!D54 -> 0
A46: Rebaja (ingresos mayores a 24,090) | D46: =+Tabla!D55 -> 0

Sheet Tabla
A1: BASE IMPONIBLE:
B2: =+Resumen!D34 -> 27664.836
B3: FB | C3: EXCESO | D3: BASICO | E3: IMPUESTO | F3: UBICACIÓN | G3: IMPUESTO
B4: 0 | C4: 11212 | D4: 0 | E4: 0 | F4: =IF(B$2<B4,0,IF(B$2>C4,0,B$2)) -> 0 | G4: =IF(F4=0,0,((F4-B4)*E4)+D4) -> 0
B5: =+C4 -> 11212 | C5: 14285 | D5: =(+C4-B4)*E4 -> 0 | E5: 0.05 | F5: =IF(B$2<B5,0,IF(B$2>C5,0,B$2)) -> 0 | G5: =IF(F5=0,0,((F5-B5)*E5)+D5) -> 0
B6: =+C5 -> 14285 | C6: 17854 | D6: =+D5+((C5-B5)*E5) -> 153.65 | E6: 0.1 | F6: =IF(B$2<B6,0,IF(B$2>C6,0,B$2)) -> 0 | G6: =IF(F6=0,0,((F6-B6)*E6)+D6) -> 0
B7: =+C6 -> 17854 | C7: 21442 | D7: =+D6+((C6-B6)*E6) -> 510.55 | E7: 0.12 | F7: =IF(B$2<B7,0,IF(B$2>C7,0,B$2)) -> 0 | G7: =IF(F7=0,0,((F7-B7)*E7)+D7) -> 0
B8: =+C7 -> 21442 | C8: 42874 | D8: =+D7+((C7-B7)*E7) -> 941.11 | E8: 0.15 | F8: =IF(B$2<B8,0,IF(B$2>C8,0,B$2)) -> 27664.836 | G8: =IF(F8=0,0,((F8-B8)*E8)+D8) -> 1874.5354
B9: =+C8 -> 42874 | C9: 64297 | D9: =+D8+((C8-B8)*E8) -> 4155.91 | E9: 0.2 | F9: =IF(B$2<B9,0,IF(B$2>C9,0,B$2)) -> 0 | G9: =IF(F9=0,0,((F9-B9)*E9)+D9) -> 0
B10: =+C9 -> 64297 | C10: 85729 | D10: =+D9+((C9-B9)*E9)-0.51 -> 8440 | E10: 0.25 | F10: =IF(B$2<B10,0,IF(B$2>C10,0,B$2)) -> 0 | G10: =IF(F10=0,0,((F10-B10)*E10)+D10) -> 0
B11: =+C10 -> 85729 | C11: 114288 | D11: =+D10+((C10-B10)*E10) -> 13798 | E11: 0.3 | F11: =IF(B$2<B11,0,IF(B$2>C11,0,B$2)) -> 0 | G11: =IF(F11=0,0,((F11-B11)*E11)+D11) -> 0
B12: =+C11 -> 114288 | D12: =+D11+((C11-B11)*E11)+0.3 -> 22366 | E12: 0.35 | F12: =IF(B$2<B12,0,B$2) -> 0 | G12: =IF(F12=0,0,((F12-B12)*E12)+D12) -> 0
B13: IMPUESTO A LA RENTA | G13: =SUM(G4:G12) -> 1874.5354
B15: Maximo deducible | D15: =+C4*1.3 -> 14575.6
B16: Enfermedad catástrofica | D16: =+C4*2 -> 22424
B17: Máximo para deducción | D17: 100000
B19: =+Resumen!D34 -> 27664.836 | C19: =+Resumen!F34 -> 30552 | F19: Empleado | H19: No empleado
B20: FB | C20: EXCESO | D20: BASICO | E20: IMPUESTO | F20: UBICACIÓN | G20: IMPUESTO
B21: 0 | C21: 11310 | D21: 0 | E21: 0 | F21: =IF(B$19<B21,0,IF(B$19>C21,0,B$19)) -> 0 | G21: =IF(F21=0,0,((F21-B21)*E21)+D21) -> 0 | H21: =IF(C$19<B21,0,IF(C$19>C21,0,C$19)) -> 0 | I21: =IF(H21=0,0,((H21-B21)*E21)+D21) -> 0
B22: =+C21+0.01 -> 11310.01 | C22: 14410 | D22: 0 | E22: 0.05 | F22: =IF(B$19<B22,0,IF(B$19>C22,0,B$19)) -> 0 | G22: =IF(F22=0,0,((F22-B22)*E22)+D22) -> 0 | H22: =IF(C$19<B22,0,IF(C$19>C22,0,C$19)) -> 0 | I22: =IF(H22=0,0,((H22-B22)*E22)+D22) -> 0
B23: =+C22+0.01 -> 14410.01 | C23: 18010 | D23: =+D22+((C22-B22)*E22) -> 154.9995 | E23: 0.1 | F23: =IF(B$19<B23,0,IF(B$19>C23,0,B$19)) -> 0 | G23: =IF(F23=0,0,((F23-B23)*E23)+D23) -> 0 | H23: =IF(C$19<B23,0,IF(C$19>C23,0,C$19)) -> 0 | I23: =IF(H23=0,0,((H23-B23)*E23)+D23) -> 0
B24: =+C23+0.01 -> 18010.01 | C24: 21630 | D24: =+D23+((C23-B23)*E23) -> 514.9985 | E24: 0.12 | F24: =IF(B$19<B24,0,IF(B$19>C24,0,B$19)) -> 0 | G24: =IF(F24=0,0,((F24-B24)*E24)+D24) -> 0 | H24: =IF(C$19<B24,0,IF(C$19>C24,0,C$19)) -> 0 | I24: =IF(H24=0,0,((H24-B24)*E24)+D24) -> 0
B25: =+C24+0.01 -> 21630.01 | C25: 31630 | D25: =+D24+((C24-B24)*E24) -> 949.3973 | E25: 0.15 | F25: =IF(B$19<B25,0,IF(B$19>C25,0,B$19)) -> 27664.836 | G25: =IF(F25=0,0,((F25-B25)*E25)+D25) -> 1854.6212 | H25: =IF(C$19<B25,0,IF(C$19>C25,0,C$19)) -> 30552 | I25: =IF(H25=0,0,((H25-B25)*E25)+D25) -> 2287.6958
B26: =+C25+0.01 -> 31630.01 | C26: 41630 | D26: =+D25+((C25-B25)*E25) -> 2449.3958 | E26: 0.2 | F26: =IF(B$19<B26,0,IF(B$19>C26,0,B$19)) -> 0 | G26: =IF(F26=0,0,((F26-B26)*E26)+D26) -> 0 | H26: =IF(C$19<B26,0,IF(C$19>C26,0,C$19)) -> 0 | I26: =IF(H26=0,0,((H26-B26)*E26)+D26) -> 0
B27: =+C26+0.01 -> 41630.01 | C27: 51630 | D27: =+D26+((C26-B26)*E26) -> 4449.3938 | E27: 0.25 | F27: =IF(B$19<B27,0,IF(B$19>C27,0,B$19)) -> 0 | G27: =IF(F27=0,0,((F27-B27)*E27)+D27) -> 0 | H27: =IF(C$19<B27,0,IF(C$19>C27,0,C$19)) -> 0 | I27: =IF(H27=0,0,((H27-B27)*E27)+D27) -> 0
B28: =+C27+0.01 -> 51630.01 | C28: 61630 | D28: =+D27+((C27-B27)*E27) -> 6949.3913 | E28: 0.3 | F28: =IF(B$19<B28,0,IF(B$19>C28,0,B$19)) -> 0 | G28: =IF(F28=0,0,((F28-B28)*E28)+D28) -> 0 | H28: =IF(C$19<B28,0,IF(C$19>C28,0,C$19)) -> 0 | I28: =IF(H28=0,0,((H28-B28)*E28)+D28) -> 0
B29: =+C28+0.01 -> 61630.01 | C29: 100000 | D29: =+D28+((C28-B28)*E28) -> 9949.3883 | E29: 0.35 | F29: =IF(B$19<B29,0,IF(B$19>C29,0,B$19)) -> 0 | G29: =IF(F29=0,0,((F29-B29)*E29)+D29) -> 0 | H29: =IF(C$19<B29,0,IF(C$19>C29,0,C$19)) -> 0 | I29: =IF(H29=0,0,((H29-B29)*E29)+D29) -> 0
B30: =+C29+0.01 -> 100000.01 | D30: =+D29+((C29-B29)*E29) -> 23378.885 | E30: 0.37 | F30: =IF(B$19<B30,0,B$19) -> 0 | G30: =IF(F30=0,0,((F30-B30)*E30)+D30) -> 0 | H30: =IF(C$19<B30,0,C$19) -> 0 | I30: =IF(H30=0,0,((H30-B30)*E30)+D30) -> 0
B31: IMPUESTO A LA RENTA | G31: =SUM(G21:G30) -> 1854.6212 | I31: =SUM(I21:I30) -> 2287.6958
B34: Ingresos totales | D34: =+Resumen!E1*12+Resumen!E3 -> 36094
B35: Límite | D35: =+C21*2.13 -> 24090.3
B36: L = CBF*7 | D36: =+Resumen!I29*7 -> 5037.55
B38: =+Resumen!E34 -> 30552
B39: FB | C39: EXCESO | D39: BASICO | E39: IMPUESTO | F39: UBICACIÓN | G39: IMPUESTO
B40: 0 | C40: 20000 | D40: 60 | E40: 0 | F40: =IF(B$38<B40,0,IF(B$38>C40,0,B$38)) -> 0 | G40: =IF(F40=0,0,((F40-B40)*E40)+D40) -> 0
B41: =+C40+0.01 -> 20000.01 | C41: 50000 | D41: 60 | E41: 0.01 | F41: =IF(B$38<B41,0,IF(B$38>C41,0,B$38)) -> 30552 | G41: =IF(F41=0,0,((F41-B41)*E41)+D41) -> 165.5199
B42: =+C41+0.01 -> 50000.01 | C42: 75000 | D42: =+D41+((C41-B41)*E41) -> 359.9999 | E42: 0.0125 | F42: =IF(B$38<B42,0,IF(B$38>C42,0,B$38)) -> 0 | G42: =IF(F42=0,0,((F42-B42)*E42)+D42) -> 0
B43: =+C42+0.01 -> 75000.01 | C43: 100000 | D43: =+D42+((C42-B42)*E42) -> 672.49977 | E43: 0.015 | F43: =IF(B$38<B43,0,IF(B$38>C43,0,B$38)) -> 0 | G43: =IF(F43=0,0,((F43-B43)*E43)+D43) -> 0
B44: =+C43+0.01 -> 100000.01 | C44: 200000 | D44: =+D43+((C43-B43)*E43) -> 1047.4996 | E44: 0.0175 | F44: =IF(B$38<B44,0,IF(B$38>C44,0,B$38)) -> 0 | G44: =IF(F44=0,0,((F44-B44)*E44)+D44) -> 0
B45: =+C44+0.01 -> 200000.01 | C45: 300000 | D45: =+D44+((C44-B44)*E44) -> 2797.4995 | E45: 0.02 | F45: =IF(B$38<B45,0,IF(B$38>C45,0,B$38)) -> 0 | G45: =IF(F45=0,0,((F45-B45)*E45)+D45) -> 0
...
